<?xml version="1.0"?>
<robot xmlns:xacro="http://ros.org/wiki/xacro">
  <xacro:macro name="rover_base_macro" params="robot_namespace *origin">
    <xacro:insert_block name="origin" />
    <link name="base_link"></link>
    <joint name="base_joint" type="fixed">
      <parent link="base_link" />
      <child link="base_link_inertial" />      
    </joint>
    <link name="base_link_inertial">
      <inertial>
        <mass value="4.298" />
        <inertia ixx="0.0243769" ixy="4.91142e-06" iyy="0.0614505" ixz="0.00236836" iyz="3.06364e-06" izz="0.072743" />
      </inertial>
      <visual>
        <origin xyz="0 0 -0" rpy="0 0 0" />
        <geometry>
            <mesh scale="1 1 1" filename="model://r1_rover/meshes/chassis_link.STL" />
        </geometry>
      </visual>
      <collision name='base_link_collision'>
        <origin xyz="0.0 0 0.15" rpy="0 0 0" />
        <geometry>
            <box size="0.455 0.426 0.32"/>
        </geometry>
      </collision>
    </link>
    <gazebo reference="base_link">
        <material>Gazebo/Grey</material>
        <selfCollide>0</selfCollide>
    </gazebo>
  </xacro:macro>

  <!-- Rotor joint and link -->
  <xacro:macro name="wheel"
    params="robot_namespace suffix direction motor_constant moment_constant parent mass_rotor radius_rotor time_constant_up time_constant_down max_rot_velocity motor_number rotor_drag_coefficient rolling_moment_coefficient color mesh mesh_scale *origin *inertia">
    <joint name="rotor_${motor_number}_joint" type="continuous">
      <xacro:insert_block name="origin" />
      <axis xyz="0 0 1" />
      <!-- TODO(ff): not currently set because it's not yet supported -->
      <!-- <limit effort="2000" velocity="${max_rot_velocity}" /> -->
      <parent link="${parent}" />
      <child link="rotor_${motor_number}" />

    </joint>
    <!-- TODO(ff): not currently set because it's not yet supported -->
    <!-- <gazebo reference="rotor_${motor_number}_joint"> <axis> <xyz>0 0 1</xyz>
      <limit> <velocity> ${max_rot_velocity} </velocity> </limit> </axis> </gazebo> -->
    <link name="rotor_${motor_number}">
      <inertial>
        <mass value="${mass_rotor}" /> <!-- [kg] -->
        <xacro:insert_block name="inertia" />
      </inertial>
      <visual>
        <origin xyz="0.0 0 -0.09" rpy="0 0.0 0" />
        <geometry>
          <mesh filename="model://plane/meshes/iris_prop_ccw.dae"
            scale="${mesh_scale}" />
        </geometry>
      </visual>
      <collision>
        <geometry>
          <cylinder length="0.005" radius="${radius_rotor}" /> <!-- [m] -->
        </geometry>
      </collision>
    </link>
    <!-- <link name='lf_wheel_link'>
      <xacro:insert_block name="origin" />
      <inertial>
        <pose>0 0 0 0 -0 0</pose>
        <mass>0.414</mass>
        <inertia>
          <ixx>0.00097298</ixx>
          <ixy>0</ixy>
          <ixz>0</ixz>
          <iyy>0.00132536</iyy>
          <iyz>0</iyz>
          <izz>0.00097299</izz>
        </inertia>
      </inertial>
      <collision name='lf_wheel_link_collision'>
        <geometry>
          <mesh>
            <scale>1 1 1</scale>
            <uri>model://r1_rover/meshes/wheel_link_simple.STL</uri>
          </mesh>
        </geometry>
        <max_contacts>1</max_contacts>
        <surface>
          <friction>
            <ode>
              <mu>200</mu>
              <mu2>100</mu2>
              <fdir1>0 0 1</fdir1>
              <slip1>0.0</slip1>
              <slip2>0.0</slip2>
            </ode>
          </friction>
          <contact>
            <ode>
              <min_depth>0.005</min_depth>
              <kp>1e8</kp>
            </ode>
          </contact>
        </surface>
      </collision>
      <visual name='lf_wheel_link_visual'>
        <pose>0 0 0 0 -0 0</pose>
        <geometry>
          <mesh>
            <scale>1 1 1</scale>
            <uri>model://r1_rover/meshes/wheel_link.STL</uri>
          </mesh>
        </geometry>
        <material>
          <script>
            <name>Gazebo/FlatBlack</name>
            <uri>file://media/materials/scripts/gazebo.material</uri>
          </script>
        </material>
      </visual>
      <gravity>1</gravity>
      <velocity_decay/>
    </link>
    <joint name='lf_wheel_joint' type='revolute'>
      <child>lf_wheel_link</child>
      <parent>base_link</parent>
      <axis>
        <xyz>0 1 0</xyz>
        <limit>
          <lower>-1e+16</lower>
          <upper>1e+16</upper>
        </limit>
        <dynamics>
          <spring_reference>0</spring_reference>
          <spring_stiffness>0</spring_stiffness>
        </dynamics>
        <use_parent_model_frame>1</use_parent_model_frame>
      </axis>
    </joint> -->
  </xacro:macro>
</robot>
